Workbook

Sheet Dashboard
A1: IT OPERATIONS — LEGACY | B1: Giá trị | C1: Ghi chú
A2: Dữ liệu | B2: SYNTHETIC | C2: Chỉ dùng cho demo
A3: Múi giờ | B3: Asia/Ho_Chi_Minh | C3: Giờ Việt Nam
A4: Tổng yêu cầu | B4: =COUNTA(Requests!A2:A60) -> 8000 | C4: Gồm cấp phát và thu hồi
A5: Yêu cầu cấp laptop | B5: =COUNTIF(Requests!C2:C60,"Laptop allocation") -> 2513
A6: Yêu cầu thu hồi laptop | B6: =COUNTIF(Requests!C2:C60,"Laptop return") -> 2269
A7: Hoàn thành | B7: =COUNTIF(Requests!D2:D60,"Completed") -> 6735
A8: Chờ duyệt | B8: =COUNTIF(Requests!D2:D60,"Pending approval") -> 135
A9: Đã duyệt | B9: =COUNTIF(Requests!D2:D60,"Approved") -> 0
A10: Đang xử lý | B10: =COUNTIF(Requests!D2:D60,"In progress") -> 135
A11: Từ chối | B11: =COUNTIF(Requests!D2:D60,"Rejected") -> 627
A12: Đã hủy | B12: =COUNTIF(Requests!D2:D60,"Cancelled") -> 368
A13: Tổng thiết bị | B13: =COUNTA(Equipment!A2:A60) -> 600
A14: Thiết bị đang cấp | B14: =COUNTIF(Equipment!D2:D60,"Assigned") -> 208
A15: Thiết bị khả dụng | B15: =COUNTIF(Equipment!D2:D60,"Available") -> 392
A16: Tổng nhân viên | B16: =COUNTA(Employees!A2:A60) -> 300 | C16: Gồm quản lý và IT
A17: Tổng sự kiện | B17: =COUNTA(RequestHistory!A2:A60) -> 29470
A18: Số kiểm tra cảnh báo | B18: =COUNTIF(DataChecks!C2:C16,"CHECK") -> 0 | C18: Xem chi tiết ở DataChecks
A19: Sự kiện mới nhất | B19: =MAX(RequestHistory!F2:F60) -> 46309.422 | C19: Thời điểm nghiệp vụ, không phải lần đọc
A20: Lưu ý | B20: Trạng thái không tự tạo lịch sử | C20: Dùng workflow để cập nhật yêu cầu và lịch sử cùng nhau
A21: Apps Script | B21: Múi giờ project chưa xác minh | C21: Cần kiểm tra trước khi chạy thêm mã ghi ngày giờ
A22: Phạm vi kiểm tra | B22: 15 quy tắc tự động | C22: Chưa thay thế kiểm tra vòng đời đầy đủ theo thời gian

Sheet Employees
A1: employee_id | B1: name | C1: department | D1: role
A2: EMP-001 | B2: An Demo | C2: Accounting | D2: Employee
A3: EMP-002 | B3: Binh Demo | C3: IT | D3: Operator
A4: EMP-003 | B4: Chi Demo | C4: Accounting | D4: Manager
A5: H-EMP-001 | B5: Demo Employee 001 | C5: Accounting | D5: Employee
A6: H-EMP-002 | B6: Demo Employee 002 | C6: Sales | D6: Employee
A7: H-EMP-003 | B7: Demo Employee 003 | C7: Operations | D7: Employee
A8: H-EMP-004 | B8: Demo Employee 004 | C8: HR | D8: Employee
A9: H-EMP-005 | B9: Demo Employee 005 | C9: Accounting | D9: Employee
A10: H-EMP-006 | B10: Demo Employee 006 | C10: Sales | D10: Employee
A11: H-EMP-007 | B11: Demo Employee 007 | C11: Operations | D11: Employee
A12: H-EMP-008 | B12: Demo Employee 008 | C12: HR | D12: Employee
... A301: G-EMP-00275 | B301: Demo Employee 300 | C301: Engineering | D301: Employee

Sheet Equipment
A1: asset_id | B1: type | C1: model | D1: status | E1: holder_id
A2: AST-001 | B2: Laptop | C2: Demo Laptop A | D2: Assigned | E2: EMP-001
A3: AST-002 | B3: Monitor | C3: Demo Monitor B | D3: Available
A4: H-AST-001 | B4: Laptop | C4: Demo Laptop 001 | D4: Available
A5: H-AST-002 | B5: Laptop | C5: Demo Laptop 002 | D5: Available
A6: H-AST-003 | B6: Laptop | C6: Demo Laptop 003 | D6: Available
A7: H-AST-004 | B7: Laptop | C7: Demo Laptop 004 | D7: Available
A8: H-AST-005 | B8: Laptop | C8: Demo Laptop 005 | D8: Available
A9: H-AST-006 | B9: Laptop | C9: Demo Laptop 006 | D9: Available
A10: H-AST-007 | B10: Laptop | C10: Demo Laptop 007 | D10: Available
A11: H-AST-008 | B11: Laptop | C11: Demo Laptop 008 | D11: Available
A12: H-AST-009 | B12: Laptop | C12: Demo Laptop 009 | D12: Available
A13: H-AST-010 | B13: Laptop | C13: Demo Laptop 010 | D13: Available
A14: H-AST-011 | B14: Laptop | C14: Demo Laptop 011 | D14: Available
... A51: H-AST-048 | B51: Laptop | C51: Demo Laptop 048 | D51: Available
A52: H-AST-049 | B52: Laptop | C52: Demo Laptop 049 | D52: Assigned | E52: H-EMP-001
A53: H-AST-050 | B53: Laptop | C53: Demo Laptop 050 | D53: Assigned | E53: H-EMP-002
A54: H-AST-051 | B54: Laptop | C54: Demo Laptop 051 | D54: Assigned | E54: H-EMP-003
A55: H-AST-052 | B55: Laptop | C55: Demo Laptop 052 | D55: Assigned | E55: H-EMP-004
A56: H-AST-053 | B56: Laptop | C56: Demo Laptop 053 | D56: Assigned | E56: H-EMP-005
A57: H-AST-054 | B57: Laptop | C57: Demo Laptop 054 | D57: Assigned | E57: H-EMP-006
A58: H-AST-055 | B58: Laptop | C58: Demo Laptop 055 | D58: Assigned | E58: H-EMP-011
A59: H-AST-056 | B59: Laptop | C59: Demo Laptop 056 | D59: Assigned | E59: H-EMP-012
A60: H-AST-057 | B60: Laptop | C60: Demo Laptop 057 | D60: Assigned | E60: H-EMP-013
A61: H-AST-058 | B61: Laptop | C61: Demo Laptop 058 | D61: Assigned | E61: H-EMP-014
A62: H-AST-059 | B62: Laptop | C62: Demo Laptop 059 | D62: Assigned | E62: H-EMP-015
A63: H-AST-060 | B63: Laptop | C63: Demo Laptop 060 | D63: Assigned | E63: H-EMP-016
... A65: G-AST-00002 | B65: Laptop | C65: Demo Fleet Engineering | D65: Assigned | E65: G-EMP-00032
A66: G-AST-00003 | B66: Laptop | C66: Demo Fleet Ultrabook | D66: Available
A67: G-AST-00004 | B67: Laptop | C67: Demo Fleet Standard | D67: Available
A68: G-AST-00005 | B68: Laptop | C68: Demo Fleet Engineering | D68: Assigned | E68: G-EMP-00273
A69: G-AST-00006 | B69: Laptop | C69: Demo Fleet Ultrabook | D69: Assigned | E69: G-EMP-00061
A70: G-AST-00007 | B70: Laptop | C70: Demo Fleet Standard | D70: Assigned | E70: G-EMP-00261
A71: G-AST-00008 | B71: Laptop | C71: Demo Fleet Engineering | D71: Assigned | E71: G-EMP-00222
A72: G-AST-00009 | B72: Laptop | C72: Demo Fleet Ultrabook | D72: Assigned | E72: G-EMP-00040
A73: G-AST-00010 | B73: Laptop | C73: Demo Fleet Standard | D73: Assigned | E73: G-EMP-00182
A74: G-AST-00011 | B74: Laptop | C74: Demo Fleet Engineering | D74: Assigned | E74: G-EMP-00228
A75: G-AST-00012 | B75: Laptop | C75: Demo Fleet Ultrabook | D75: Available
A76: G-AST-00013 | B76: Laptop | C76: Demo Fleet Standard | D76: Assigned | E76: G-EMP-00176
A77: G-AST-00014 | B77: Laptop | C77: Demo Fleet Engineering | D77: Assigned | E77: G-EMP-00084
...

Sheet Requests
A1: request_id | B1: employee_id | C1: request_type | D1: status | E1: assigned_to | F1: asset_id | G1: created_at
A2: REQ-001 | B2: EMP-001 | C2: Laptop allocation | D2: Completed | E2: EMP-002 | F2: AST-001 | G2: 46309.417
A3: H-REQ-001 | B3: H-EMP-001 | C3: Laptop allocation | D3: Completed | E3: H-OPERATOR | F3: H-AST-001 | G3: 45761.292
A4: H-REQ-002 | B4: H-EMP-002 | C4: Laptop allocation | D4: Completed | E4: H-OPERATOR | F4: H-AST-002 | G4: 45766.292
A5: H-REQ-003 | B5: H-EMP-003 | C5: Laptop allocation | D5: Completed | E5: H-OPERATOR | F5: H-AST-003 | G5: 45771.292
A6: H-REQ-004 | B6: H-EMP-004 | C6: Laptop allocation | D6: Completed | E6: H-OPERATOR | F6: H-AST-004 | G6: 45776.292
A7: H-REQ-005 | B7: H-EMP-005 | C7: Laptop allocation | D7: Completed | E7: H-OPERATOR | F7: H-AST-005 | G7: 45781.292
A8: H-REQ-006 | B8: H-EMP-006 | C8: Laptop allocation | D8: Completed | E8: H-OPERATOR | F8: H-AST-006 | G8: 45786.292
A9: H-REQ-007 | B9: H-EMP-007 | C9: Laptop allocation | D9: Rejected | G9: 45791.292
A10: H-REQ-008 | B10: H-EMP-008 | C10: Laptop allocation | D10: Cancelled | G10: 45796.292
A11: H-REQ-009 | B11: H-EMP-009 | C11: Laptop allocation | D11: In progress | E11: H-OPERATOR | G11: 46306.292
A12: H-REQ-010 | B12: H-EMP-010 | C12: Laptop allocation | D12: Pending approval | G12: 46305.292
A13: H-REQ-011 | B13: H-EMP-011 | C13: Laptop allocation | D13: Completed | E13: H-OPERATOR | F13: H-AST-007 | G13: 45811.292
A14: H-REQ-012 | B14: H-EMP-012 | C14: Laptop allocation | D14: Completed | E14: H-OPERATOR | F14: H-AST-008 | G14: 45816.292
A15: H-REQ-013 | B15: H-EMP-013 | C15: Laptop allocation | D15: Completed | E15: H-OPERATOR | F15: H-AST-009 | G15: 45821.292
A16: H-REQ-014 | B16: H-EMP-014 | C16: Laptop allocation | D16: Completed | E16: H-OPERATOR | F16: H-AST-010 | G16: 45826.292
A17: H-REQ-015 | B17: H-EMP-015 | C17: Laptop allocation | D17: Completed | E17: H-OPERATOR | F17: H-AST-011 | G17: 45831.292
A18: H-REQ-016 | B18: H-EMP-016 | C18: Laptop allocation | D18: Completed | E18: H-OPERATOR | F18: H-AST-012 | G18: 45836.292
A19: H-REQ-017 | B19: H-EMP-017 | C19: Laptop allocation | D19: Rejected | G19: 45841.292
A20: H-REQ-018 | B20: H-EMP-018 | C20: Laptop allocation | D20: Cancelled | G20: 45846.292
A21: H-REQ-019 | B21: H-EMP-019 | C21: Laptop allocation | D21: In progress | E21: H-OPERATOR | G21: 46303.292
A22: H-REQ-020 | B22: H-EMP-020 | C22: Laptop allocation | D22: Pending approval | G22: 46302.292
A23: H-REQ-021 | B23: H-EMP-001 | C23: Laptop allocation | D23: Completed | E23: H-OPERATOR | F23: H-AST-013 | G23: 45861.292
A24: H-REQ-022 | B24: H-EMP-002 | C24: Laptop allocation | D24: Completed | E24: H-OPERATOR | F24: H-AST-014 | G24: 45866.292
A25: H-REQ-023 | B25: H-EMP-003 | C25: Laptop allocation | D25: Completed | E25: H-OPERATOR | F25: H-AST-015 | G25: 45871.292
A26: H-REQ-024 | B26: H-EMP-004 | C26: Laptop allocation | D26: Completed | E26: H-OPERATOR | F26: H-AST-016 | G26: 45876.292
A27: H-REQ-025 | B27: H-EMP-005 | C27: Laptop allocation | D27: Completed | E27: H-OPERATOR | F27: H-AST-017 | G27: 45881.292
A28: H-REQ-026 | B28: H-EMP-006 | C28: Laptop allocation | D28: Completed | E28: H-OPERATOR | F28: H-AST-018 | G28: 45886.292
A29: H-REQ-027 | B29: H-EMP-007 | C29: Laptop allocation | D29: Rejected | G29: 45891.292
A30: H-REQ-028 | B30: H-EMP-008 | C30: Laptop allocation | D30: Cancelled | G30: 45896.292
A31: H-REQ-029 | B31: H-EMP-009 | C31: Laptop allocation | D31: In progress | E31: H-OPERATOR | G31: 46307.292
A32: H-REQ-030 | B32: H-EMP-010 | C32: Laptop allocation | D32: Pending approval | G32: 46306.292
A33: H-REQ-031 | B33: H-EMP-011 | C33: Laptop allocation | D33: Completed | E33: H-OPERATOR | F33: H-AST-019 | G33: 45911.292
A34: H-REQ-032 | B34: H-EMP-012 | C34: Laptop allocation | D34: Completed | E34: H-OPERATOR | F34: H-AST-020 | G34: 45916.292
A35: H-REQ-033 | B35: H-EMP-013 | C35: Laptop allocation | D35: Completed | E35: H-OPERATOR | F35: H-AST-021 | G35: 45921.292
A36: H-REQ-034 | B36: H-EMP-014 | C36: Laptop allocation | D36: Completed | E36: H-OPERATOR | F36: H-AST-022 | G36: 45926.292
A37: H-REQ-035 | B37: H-EMP-015 | C37: Laptop allocation | D37: Completed | E37: H-OPERATOR | F37: H-AST-023 | G37: 45931.292
A38: H-REQ-036 | B38: H-EMP-016 | C38: Laptop allocation | D38: Completed | E38: H-OPERATOR | F38: H-AST-024 | G38: 45936.292
A39: H-REQ-037 | B39: H-EMP-017 | C39: Laptop allocation | D39: Rejected | G39: 45941.292
A40: H-REQ-038 | B40: H-EMP-018 | C40: Laptop allocation | D40: Cancelled | G40: 45946.292
...

Sheet RequestHistory
A1: event_id | B1: request_id | C1: from_status | D1: to_status | E1: actor_id | F1: occurred_at | G1: note
A2: EVT-001 | B2: REQ-001 | D2: Pending approval | E2: EMP-001 | F2: 46309.417 | G2: Synthetic demo: employee submitted a request
A3: EVT-002 | B3: REQ-001 | C3: Pending approval | D3: Approved | E3: EMP-003 | F3: 46309.419 | G3: Manager approved laptop allocation
A4: 510d6c10-49c9-4e8a-a3a4-2680d9d8a3b9 | B4: REQ-001 | C4: Approved | D4: In progress | E4: EMP-002 | F4: 46309.422 | G4: Demo: Binh accepted the request
A5: 8c255699-dc38-4c03-8dfe-c963fd8a0150 | B5: REQ-001 | C5: In progress | D5: Completed | E5: EMP-002 | F5: 46309.422 | G5: Demo: handed over AST-001 to EMP-001
A6: H-REQ-001-E1 | B6: H-REQ-001 | D6: Pending approval | E6: H-EMP-001 | F6: 45761.292 | G6: SYNTHETIC: Request submitted
A7: H-REQ-001-E2 | B7: H-REQ-001 | C7: Pending approval | D7: Approved | E7: H-MANAGER | F7: 45761.542 | G7: SYNTHETIC: Request approved
A8: H-REQ-001-E3 | B8: H-REQ-001 | C8: Approved | D8: In progress | E8: H-OPERATOR | F8: 45761.792 | G8: SYNTHETIC: IT accepted request
A9: H-REQ-001-E4 | B9: H-REQ-001 | C9: In progress | D9: Completed | E9: H-OPERATOR | F9: 45763.292 | G9: SYNTHETIC: Handed over H-AST-001
A10: H-REQ-002-E1 | B10: H-REQ-002 | D10: Pending approval | E10: H-EMP-002 | F10: 45766.292 | G10: SYNTHETIC: Request submitted
A11: H-REQ-002-E2 | B11: H-REQ-002 | C11: Pending approval | D11: Approved | E11: H-MANAGER | F11: 45766.542 | G11: SYNTHETIC: Request approved
A12: H-REQ-002-E3 | B12: H-REQ-002 | C12: Approved | D12: In progress | E12: H-OPERATOR | F12: 45766.792 | G12: SYNTHETIC: IT accepted request
A13: H-REQ-002-E4 | B13: H-REQ-002 | C13: In progress | D13: Completed | E13: H-OPERATOR | F13: 45768.292 | G13: SYNTHETIC: Handed over H-AST-002
A14: H-REQ-003-E1 | B14: H-REQ-003 | D14: Pending approval | E14: H-EMP-003 | F14: 45771.292 | G14: SYNTHETIC: Request submitted
A15: H-REQ-003-E2 | B15: H-REQ-003 | C15: Pending approval | D15: Approved | E15: H-MANAGER | F15: 45771.542 | G15: SYNTHETIC: Request approved
A16: H-REQ-003-E3 | B16: H-REQ-003 | C16: Approved | D16: In progress | E16: H-OPERATOR | F16: 45771.792 | G16: SYNTHETIC: IT accepted request
A17: H-REQ-003-E4 | B17: H-REQ-003 | C17: In progress | D17: Completed | E17: H-OPERATOR | F17: 45773.292 | G17: SYNTHETIC: Handed over H-AST-003
A18: H-REQ-004-E1 | B18: H-REQ-004 | D18: Pending approval | E18: H-EMP-004 | F18: 45776.292 | G18: SYNTHETIC: Request submitted
A19: H-REQ-004-E2 | B19: H-REQ-004 | C19: Pending approval | D19: Approved | E19: H-MANAGER | F19: 45776.542 | G19: SYNTHETIC: Request approved
A20: H-REQ-004-E3 | B20: H-REQ-004 | C20: Approved | D20: In progress | E20: H-OPERATOR | F20: 45776.792 | G20: SYNTHETIC: IT accepted request
A21: H-REQ-004-E4 | B21: H-REQ-004 | C21: In progress | D21: Completed | E21: H-OPERATOR | F21: 45778.292 | G21: SYNTHETIC: Handed over H-AST-004
A22: H-REQ-005-E1 | B22: H-REQ-005 | D22: Pending approval | E22: H-EMP-005 | F22: 45781.292 | G22: SYNTHETIC: Request submitted
A23: H-REQ-005-E2 | B23: H-REQ-005 | C23: Pending approval | D23: Approved | E23: H-MANAGER | F23: 45781.542 | G23: SYNTHETIC: Request approved
A24: H-REQ-005-E3 | B24: H-REQ-005 | C24: Approved | D24: In progress | E24: H-OPERATOR | F24: 45781.792 | G24: SYNTHETIC: IT accepted request
A25: H-REQ-005-E4 | B25: H-REQ-005 | C25: In progress | D25: Completed | E25: H-OPERATOR | F25: 45783.292 | G25: SYNTHETIC: Handed over H-AST-005
A26: H-REQ-006-E1 | B26: H-REQ-006 | D26: Pending approval | E26: H-EMP-006 | F26: 45786.292 | G26: SYNTHETIC: Request submitted
A27: H-REQ-006-E2 | B27: H-REQ-006 | C27: Pending approval | D27: Approved | E27: H-MANAGER | F27: 45786.542 | G27: SYNTHETIC: Request approved
A28: H-REQ-006-E3 | B28: H-REQ-006 | C28: Approved | D28: In progress | E28: H-OPERATOR | F28: 45786.792 | G28: SYNTHETIC: IT accepted request
A29: H-REQ-006-E4 | B29: H-REQ-006 | C29: In progress | D29: Completed | E29: H-OPERATOR | F29: 45788.292 | G29: SYNTHETIC: Handed over H-AST-006
A30: H-REQ-007-E1 | B30: H-REQ-007 | D30: Pending approval | E30: H-EMP-007 | F30: 45791.292 | G30: SYNTHETIC: Request submitted
A31: H-REQ-007-E2 | B31: H-REQ-007 | C31: Pending approval | D31: Rejected | E31: H-MANAGER | F31: 45792.292 | G31: SYNTHETIC: Request rejected
A32: H-REQ-008-E1 | B32: H-REQ-008 | D32: Pending approval | E32: H-EMP-008 | F32: 45796.292 | G32: SYNTHETIC: Request submitted
A33: H-REQ-008-E2 | B33: H-REQ-008 | C33: Pending approval | D33: Cancelled | E33: H-EMP-008 | F33: 45797.292 | G33: SYNTHETIC: Requester cancelled
A34: H-REQ-009-E1 | B34: H-REQ-009 | D34: Pending approval | E34: H-EMP-009 | F34: 46306.292 | G34: SYNTHETIC: Request submitted
A35: H-REQ-009-E2 | B35: H-REQ-009 | C35: Pending approval | D35: Approved | E35: H-MANAGER | F35: 46306.542 | G35: SYNTHETIC: Request approved
A36: H-REQ-009-E3 | B36: H-REQ-009 | C36: Approved | D36: In progress | E36: H-OPERATOR | F36: 46306.792 | G36: SYNTHETIC: IT accepted request
A37: H-REQ-010-E1 | B37: H-REQ-010 | D37: Pending approval | E37: H-EMP-010 | F37: 46305.292 | G37: SYNTHETIC: Request submitted
A38: H-REQ-011-E1 | B38: H-REQ-011 | D38: Pending approval | E38: H-EMP-011 | F38: 45811.292 | G38: SYNTHETIC: Request submitted
A39: H-REQ-011-E2 | B39: H-REQ-011 | C39: Pending approval | D39: Approved | E39: H-MANAGER | F39: 45811.542 | G39: SYNTHETIC: Request approved
A40: H-REQ-011-E3 | B40: H-REQ-011 | C40: Approved | D40: In progress | E40: H-OPERATOR | F40: 45811.792 | G40: SYNTHETIC: IT accepted request
...

Sheet Attachments
A1: attachment_id | B1: request_id | C1: drive_file_id | D1: name

Sheet Settings
A1: key | B1: value
A2: demo_data | B2: SYNTHETIC
A3: email_enabled | B3: FALSE
A4: schema_version | B4: 1
A5: business_timezone | B5: Asia/Ho_Chi_Minh
A6: timestamp_storage | B6: Local date-time in Asia/Ho_Chi_Minh
A7: history_repair_version | B7: 2
A8: laptop_policy | B8: At most one assigned laptop per employee
A9: script_timezone_status | B9: Not verified: set Apps Script project timezone before new runs

Sheet DataChecks
A1: Kiểm tra | B1: Số lỗi | C1: Kết quả | D1: Phạm vi
A2: Trùng mã nhân viên | B2: =IFERROR(__xludf.DUMMYFUNCTION("COUNTA(Employees!A2:A40)-IFERROR(COUNTUNIQUE(FILTER(Employees!A2:A40,Employees!A2:A40<>"""")),0)"),0.0) -> 0 | C2: =IF(B2=0,"PASS","CHECK") -> PASS | D2: Số ID lặp ngoài lần xuất hiện đầu
A3: Trùng mã thiết bị | B3: =IFERROR(__xludf.DUMMYFUNCTION("COUNTA(Equipment!A2:A40)-IFERROR(COUNTUNIQUE(FILTER(Equipment!A2:A40,Equipment!A2:A40<>"""")),0)"),0.0) -> 0 | C3: =IF(B3=0,"PASS","CHECK") -> PASS | D3: Số ID lặp
A4: Trùng mã yêu cầu | B4: =IFERROR(__xludf.DUMMYFUNCTION("COUNTA(Requests!A2:A40)-IFERROR(COUNTUNIQUE(FILTER(Requests!A2:A40,Requests!A2:A40<>"""")),0)"),0.0) -> 0 | C4: =IF(B4=0,"PASS","CHECK") -> PASS | D4: Số ID lặp
A5: Trùng mã sự kiện | B5: =IFERROR(__xludf.DUMMYFUNCTION("COUNTA(RequestHistory!A2:A40)-IFERROR(COUNTUNIQUE(FILTER(RequestHistory!A2:A40,RequestHistory!A2:A40<>"""")),0)"),0.0) -> 0 | C5: =IF(B5=0,"PASS","CHECK") -> PASS | D5: Số ID lặp
A6: Người yêu cầu không tồn tại | B6: {=SUM((Requests!A2:A40<>"")*(COUNTIF(Employees!A2:A40,Requests!B2:B40)=0))} -> 0 | C6: =IF(B6=0,"PASS","CHECK") -> PASS | D6: Kiểm tra liên kết nhân viên
A7: Người xử lý không tồn tại | B7: {=SUM((Requests!E2:E40<>"")*(COUNTIF(Employees!A2:A40,Requests!E2:E40)=0))} -> 0 | C7: =IF(B7=0,"PASS","CHECK") -> PASS | D7: Bỏ qua yêu cầu chưa phân công
A8: Lịch sử không có yêu cầu | B8: {=SUM((RequestHistory!A2:A40<>"")*(COUNTIF(Requests!A2:A40,RequestHistory!B2:B40)=0))} -> 0 | C8: =IF(B8=0,"PASS","CHECK") -> PASS | D8: Kiểm tra request_id
A9: Người thực hiện không tồn tại | B9: {=SUM((RequestHistory!A2:A40<>"")*(COUNTIF(Employees!A2:A40,RequestHistory!E2:E40)=0))} -> 0 | C9: =IF(B9=0,"PASS","CHECK") -> PASS | D9: Kiểm tra actor_id
A10: Hoàn thành thiếu thiết bị | B10: {=SUM((Requests!A2:A40<>"")*(Requests!D2:D40="Completed")*(COUNTIF(Equipment!A2:A40,Requests!F2:F40)=0))} -> 0 | C10: =IF(B10=0,"PASS","CHECK") -> PASS | D10: Áp dụng cấp phát và thu hồi laptop
A11: Người giữ thiết bị không hợp lệ | B11: {=SUM((Equipment!D2:D40="Assigned")*(COUNTIF(Employees!A2:A40,Equipment!E2:E40)=0))} -> 0 | C11: =IF(B11=0,"PASS","CHECK") -> PASS | D11: Assigned phải có nhân viên tồn tại
A12: Thiết bị khả dụng còn người giữ | B12: {=SUM((Equipment!D2:D40="Available")*(LEN(Equipment!E2:E40)>0))} -> 0 | C12: =IF(B12=0,"PASS","CHECK") -> PASS | D12: Available phải để trống holder_id
A13: Nhân viên giữ hơn một laptop | B13: =IFERROR(__xludf.DUMMYFUNCTION("SUM(MAP(FILTER(Employees!A2:A40,Employees!A2:A40<>""""),LAMBDA(emp,IF(COUNTIFS(Equipment!B2:B40,""Laptop"",Equipment!D2:D40,""Assigned"",Equipment!E2:E40,emp)>1,1,0))))"),0.0) -> 0 | C13: =IF(B13=0,"PASS","CHECK") -> PASS | D13: Số nhân viên vi phạm
A14: Trạng thái lệch sự kiện mới nhất | B14: 0 | C14: =IF(B14=0,"PASS","CHECK") -> PASS | D14: So sánh sự kiện có thời điểm lớn nhất
A15: Ngày tạo không phải kiểu ngày số | B15: =COUNTA(Requests!A2:A40)-COUNT(Requests!G2:G40) -> 0 | C15: =IF(B15=0,"PASS","CHECK") -> PASS | D15: Không phát hiện mọi lỗi múi giờ
A16: Ngày sự kiện không phải kiểu ngày số | B16: =COUNTA(RequestHistory!A2:A40)-COUNT(RequestHistory!F2:F40) -> 0 | C16: =IF(B16=0,"PASS","CHECK") -> PASS | D16: Ngày lưu dạng text sẽ bị báo

Sheet LatestEvents
A1: request_id | B1: occurred_at | C1: source_row | D1: status
A2: =IFERROR(__xludf.DUMMYFUNCTION("SORTN(SORT(FILTER({RequestHistory!B2:B9000,RequestHistory!F2:F9000,ROW(RequestHistory!A2:A9000),RequestHistory!D2:D9000},RequestHistory!B2:B9000<>""""),2,FALSE,3,FALSE),9^9,2,1,TRUE)"),"G-REQ-00001") -> G-REQ-00001 | B2: =IFERROR(__xludf.DUMMYFUNCTION("""COMPUTED_VALUE"""),45761.38541666666) -> 45761.385 | C2: =IFERROR(__xludf.DUMMYFUNCTION("""COMPUTED_VALUE"""),521.0) -> 521 | D2: =IFERROR(__xludf.DUMMYFUNCTION("""COMPUTED_VALUE"""),"Completed") -> Completed
A3: =IFERROR(__xludf.DUMMYFUNCTION("""COMPUTED_VALUE"""),"G-REQ-00002") -> G-REQ-00002 | B3: =IFERROR(__xludf.DUMMYFUNCTION("""COMPUTED_VALUE"""),45761.45659151208) -> 45761.457 | C3: =IFERROR(__xludf.DUMMYFUNCTION("""COMPUTED_VALUE"""),525.0) -> 525 | D3: =IFERROR(__xludf.DUMMYFUNCTION("""COMPUTED_VALUE"""),"Completed") -> Completed
A4: =IFERROR(__xludf.DUMMYFUNCTION("""COMPUTED_VALUE"""),"G-REQ-00003") -> G-REQ-00003 | B4: =IFERROR(__xludf.DUMMYFUNCTION("""COMPUTED_VALUE"""),45761.527766357496) -> 45761.528 | C4: =IFERROR(__xludf.DUMMYFUNCTION("""COMPUTED_VALUE"""),529.0) -> 529 | D4: =IFERROR(__xludf.DUMMYFUNCTION("""COMPUTED_VALUE"""),"Completed") -> Completed
A5: =IFERROR(__xludf.DUMMYFUNCTION("""COMPUTED_VALUE"""),"G-REQ-00004") -> G-REQ-00004 | B5: =IFERROR(__xludf.DUMMYFUNCTION("""COMPUTED_VALUE"""),45761.59199675846) -> 45761.592 | C5: =IFERROR(__xludf.DUMMYFUNCTION("""COMPUTED_VALUE"""),531.0) -> 531 | D5: =IFERROR(__xludf.DUMMYFUNCTION("""COMPUTED_VALUE"""),"Rejected") -> Rejected
A6: =IFERROR(__xludf.DUMMYFUNCTION("""COMPUTED_VALUE"""),"G-REQ-00005") -> G-REQ-00005 | B6: =IFERROR(__xludf.DUMMYFUNCTION("""COMPUTED_VALUE"""),45761.663171603876) -> 45761.663 | C6: =IFERROR(__xludf.DUMMYFUNCTION("""COMPUTED_VALUE"""),533.0) -> 533 | D6: =IFERROR(__xludf.DUMMYFUNCTION("""COMPUTED_VALUE"""),"Rejected") -> Rejected
A7: =IFERROR(__xludf.DUMMYFUNCTION("""COMPUTED_VALUE"""),"G-REQ-00006") -> G-REQ-00006 | B7: =IFERROR(__xludf.DUMMYFUNCTION("""COMPUTED_VALUE"""),45761.74129089374) -> 45761.741 | C7: =IFERROR(__xludf.DUMMYFUNCTION("""COMPUTED_VALUE"""),537.0) -> 537 | D7: =IFERROR(__xludf.DUMMYFUNCTION("""COMPUTED_VALUE"""),"Completed") -> Completed
A8: =IFERROR(__xludf.DUMMYFUNCTION("""COMPUTED_VALUE"""),"G-REQ-00007") -> G-REQ-00007 | B8: =IFERROR(__xludf.DUMMYFUNCTION("""COMPUTED_VALUE"""),45761.81246573915) -> 45761.812 | C8: =IFERROR(__xludf.DUMMYFUNCTION("""COMPUTED_VALUE"""),541.0) -> 541 | D8: =IFERROR(__xludf.DUMMYFUNCTION("""COMPUTED_VALUE"""),"Completed") -> Completed
A9: =IFERROR(__xludf.DUMMYFUNCTION("""COMPUTED_VALUE"""),"G-REQ-00008") -> G-REQ-00008 | B9: =IFERROR(__xludf.DUMMYFUNCTION("""COMPUTED_VALUE"""),45761.87669614012) -> 45761.877 | C9: =IFERROR(__xludf.DUMMYFUNCTION("""COMPUTED_VALUE"""),543.0) -> 543 | D9: =IFERROR(__xludf.DUMMYFUNCTION("""COMPUTED_VALUE"""),"Rejected") -> Rejected
A10: =IFERROR(__xludf.DUMMYFUNCTION("""COMPUTED_VALUE"""),"G-REQ-00009") -> G-REQ-00009 | B10: =IFERROR(__xludf.DUMMYFUNCTION("""COMPUTED_VALUE"""),45761.954815429985) -> 45761.955 | C10: =IFERROR(__xludf.DUMMYFUNCTION("""COMPUTED_VALUE"""),547.0) -> 547 | D10: =IFERROR(__xludf.DUMMYFUNCTION("""COMPUTED_VALUE"""),"Completed") -> Completed
A11: =IFERROR(__xludf.DUMMYFUNCTION("""COMPUTED_VALUE"""),"G-REQ-00010") -> G-REQ-00010 | B11: =IFERROR(__xludf.DUMMYFUNCTION("""COMPUTED_VALUE"""),45762.0259902754) -> 45762.026 | C11: =IFERROR(__xludf.DUMMYFUNCTION("""COMPUTED_VALUE"""),551.0) -> 551 | D11: =IFERROR(__xludf.DUMMYFUNCTION("""COMPUTED_VALUE"""),"Completed") -> Completed
A12: =IFERROR(__xludf.DUMMYFUNCTION("""COMPUTED_VALUE"""),"G-REQ-00011") -> G-REQ-00011 | B12: =IFERROR(__xludf.DUMMYFUNCTION("""COMPUTED_VALUE"""),45762.09716512081) -> 45762.097 | C12: =IFERROR(__xludf.DUMMYFUNCTION("""COMPUTED_VALUE"""),555.0) -> 555 | D12: =IFERROR(__xludf.DUMMYFUNCTION("""COMPUTED_VALUE"""),"Completed") -> Completed
A13: =IFERROR(__xludf.DUMMYFUNCTION("""COMPUTED_VALUE"""),"G-REQ-00012") -> G-REQ-00012 | B13: =IFERROR(__xludf.DUMMYFUNCTION("""COMPUTED_VALUE"""),45762.16833996623) -> 45762.168 | C13: =IFERROR(__xludf.DUMMYFUNCTION("""COMPUTED_VALUE"""),559.0) -> 559 | D13: =IFERROR(__xludf.DUMMYFUNCTION("""COMPUTED_VALUE"""),"Completed") -> Completed
A14: =IFERROR(__xludf.DUMMYFUNCTION("""COMPUTED_VALUE"""),"G-REQ-00013") -> G-REQ-00013 | B14: =IFERROR(__xludf.DUMMYFUNCTION("""COMPUTED_VALUE"""),45762.23951481164) -> 45762.24 | C14: =IFERROR(__xludf.DUMMYFUNCTION("""COMPUTED_VALUE"""),563.0) -> 563 | D14: =IFERROR(__xludf.DUMMYFUNCTION("""COMPUTED_VALUE"""),"Completed") -> Completed
A15: =IFERROR(__xludf.DUMMYFUNCTION("""COMPUTED_VALUE"""),"G-REQ-00014") -> G-REQ-00014 | B15: =IFERROR(__xludf.DUMMYFUNCTION("""COMPUTED_VALUE"""),45762.31068965705) -> 45762.311 | C15: =IFERROR(__xludf.DUMMYFUNCTION("""COMPUTED_VALUE"""),567.0) -> 567 | D15: =IFERROR(__xludf.DUMMYFUNCTION("""COMPUTED_VALUE"""),"Completed") -> Completed
A16: =IFERROR(__xludf.DUMMYFUNCTION("""COMPUTED_VALUE"""),"G-REQ-00015") -> G-REQ-00015 | B16: =IFERROR(__xludf.DUMMYFUNCTION("""COMPUTED_VALUE"""),45762.38186450247) -> 45762.382 | C16: =IFERROR(__xludf.DUMMYFUNCTION("""COMPUTED_VALUE"""),571.0) -> 571 | D16: =IFERROR(__xludf.DUMMYFUNCTION("""COMPUTED_VALUE"""),"Completed") -> Completed
A17: =IFERROR(__xludf.DUMMYFUNCTION("""COMPUTED_VALUE"""),"G-REQ-00016") -> G-REQ-00016 | B17: =IFERROR(__xludf.DUMMYFUNCTION("""COMPUTED_VALUE"""),45762.44609490345) -> 45762.446 | C17: =IFERROR(__xludf.DUMMYFUNCTION("""COMPUTED_VALUE"""),573.0) -> 573 | D17: =IFERROR(__xludf.DUMMYFUNCTION("""COMPUTED_VALUE"""),"Rejected") -> Rejected
A18: =IFERROR(__xludf.DUMMYFUNCTION("""COMPUTED_VALUE"""),"G-REQ-00017") -> G-REQ-00017 | B18: =IFERROR(__xludf.DUMMYFUNCTION("""COMPUTED_VALUE"""),45762.5242141933) -> 45762.524 | C18: =IFERROR(__xludf.DUMMYFUNCTION("""COMPUTED_VALUE"""),577.0) -> 577 | D18: =IFERROR(__xludf.DUMMYFUNCTION("""COMPUTED_VALUE"""),"Completed") -> Completed
A19: =IFERROR(__xludf.DUMMYFUNCTION("""COMPUTED_VALUE"""),"G-REQ-00018") -> G-REQ-00018 | B19: =IFERROR(__xludf.DUMMYFUNCTION("""COMPUTED_VALUE"""),45762.59538903872) -> 45762.595 | C19: =IFERROR(__xludf.DUMMYFUNCTION("""COMPUTED_VALUE"""),581.0) -> 581 | D19: =IFERROR(__xludf.DUMMYFUNCTION("""COMPUTED_VALUE"""),"Completed") -> Completed
A20: =IFERROR(__xludf.DUMMYFUNCTION("""COMPUTED_VALUE"""),"G-REQ-00019") -> G-REQ-00019 | B20: =IFERROR(__xludf.DUMMYFUNCTION("""COMPUTED_VALUE"""),45762.66656388414) -> 45762.667 | C20: =IFERROR(__xludf.DUMMYFUNCTION("""COMPUTED_VALUE"""),585.0) -> 585 | D20: =IFERROR(__xludf.DUMMYFUNCTION("""COMPUTED_VALUE"""),"Completed") -> Completed
A21: =IFERROR(__xludf.DUMMYFUNCTION("""COMPUTED_VALUE"""),"G-REQ-00020") -> G-REQ-00020 | B21: =IFERROR(__xludf.DUMMYFUNCTION("""COMPUTED_VALUE"""),45762.73773872955) -> 45762.738 | C21: =IFERROR(__xludf.DUMMYFUNCTION("""COMPUTED_VALUE"""),589.0) -> 589 | D21: =IFERROR(__xludf.DUMMYFUNCTION("""COMPUTED_VALUE"""),"Completed") -> Completed
A22: =IFERROR(__xludf.DUMMYFUNCTION("""COMPUTED_VALUE"""),"G-REQ-00021") -> G-REQ-00021 | B22: =IFERROR(__xludf.DUMMYFUNCTION("""COMPUTED_VALUE"""),45762.801969130516) -> 45762.802 | C22: =IFERROR(__xludf.DUMMYFUNCTION("""COMPUTED_VALUE"""),591.0) -> 591 | D22: =IFERROR(__xludf.DUMMYFUNCTION("""COMPUTED_VALUE"""),"Rejected") -> Rejected
A23: =IFERROR(__xludf.DUMMYFUNCTION("""COMPUTED_VALUE"""),"G-REQ-00022") -> G-REQ-00022 | B23: =IFERROR(__xludf.DUMMYFUNCTION("""COMPUTED_VALUE"""),45762.88008842038) -> 45762.88 | C23: =IFERROR(__xludf.DUMMYFUNCTION("""COMPUTED_VALUE"""),595.0) -> 595 | D23: =IFERROR(__xludf.DUMMYFUNCTION("""COMPUTED_VALUE"""),"Completed") -> Completed
A24: =IFERROR(__xludf.DUMMYFUNCTION("""COMPUTED_VALUE"""),"G-REQ-00023") -> G-REQ-00023 | B24: =IFERROR(__xludf.DUMMYFUNCTION("""COMPUTED_VALUE"""),45762.95126326579) -> 45762.951 | C24: =IFERROR(__xludf.DUMMYFUNCTION("""COMPUTED_VALUE"""),599.0) -> 599 | D24: =IFERROR(__xludf.DUMMYFUNCTION("""COMPUTED_VALUE"""),"Completed") -> Completed
A25: =IFERROR(__xludf.DUMMYFUNCTION("""COMPUTED_VALUE"""),"G-REQ-00024") -> G-REQ-00024 | B25: =IFERROR(__xludf.DUMMYFUNCTION("""COMPUTED_VALUE"""),45763.022438111206) -> 45763.022 | C25: =IFERROR(__xludf.DUMMYFUNCTION("""COMPUTED_VALUE"""),603.0) -> 603 | D25: =IFERROR(__xludf.DUMMYFUNCTION("""COMPUTED_VALUE"""),"Completed") -> Completed
A26: =IFERROR(__xludf.DUMMYFUNCTION("""COMPUTED_VALUE"""),"G-REQ-00025") -> G-REQ-00025 | B26: =IFERROR(__xludf.DUMMYFUNCTION("""COMPUTED_VALUE"""),45763.093612956625) -> 45763.094 | C26: =IFERROR(__xludf.DUMMYFUNCTION("""COMPUTED_VALUE"""),607.0) -> 607 | D26: =IFERROR(__xludf.DUMMYFUNCTION("""COMPUTED_VALUE"""),"Completed") -> Completed
A27: =IFERROR(__xludf.DUMMYFUNCTION("""COMPUTED_VALUE"""),"G-REQ-00026") -> G-REQ-00026 | B27: =IFERROR(__xludf.DUMMYFUNCTION("""COMPUTED_VALUE"""),45763.164787802045) -> 45763.165 | C27: =IFERROR(__xludf.DUMMYFUNCTION("""COMPUTED_VALUE"""),611.0) -> 611 | D27: =IFERROR(__xludf.DUMMYFUNCTION("""COMPUTED_VALUE"""),"Completed") -> Completed
A28: =IFERROR(__xludf.DUMMYFUNCTION("""COMPUTED_VALUE"""),"G-REQ-00027") -> G-REQ-00027 | B28: =IFERROR(__xludf.DUMMYFUNCTION("""COMPUTED_VALUE"""),45763.229018203005) -> 45763.229 | C28: =IFERROR(__xludf.DUMMYFUNCTION("""COMPUTED_VALUE"""),613.0) -> 613 | D28: =IFERROR(__xludf.DUMMYFUNCTION("""COMPUTED_VALUE"""),"Rejected") -> Rejected
A29: =IFERROR(__xludf.DUMMYFUNCTION("""COMPUTED_VALUE"""),"G-REQ-00028") -> G-REQ-00028 | B29: =IFERROR(__xludf.DUMMYFUNCTION("""COMPUTED_VALUE"""),45763.30713749287) -> 45763.307 | C29: =IFERROR(__xludf.DUMMYFUNCTION("""COMPUTED_VALUE"""),617.0) -> 617 | D29: =IFERROR(__xludf.DUMMYFUNCTION("""COMPUTED_VALUE"""),"Completed") -> Completed
A30: =IFERROR(__xludf.DUMMYFUNCTION("""COMPUTED_VALUE"""),"G-REQ-00029") -> G-REQ-00029 | B30: =IFERROR(__xludf.DUMMYFUNCTION("""COMPUTED_VALUE"""),45763.37831233828) -> 45763.378 | C30: =IFERROR(__xludf.DUMMYFUNCTION("""COMPUTED_VALUE"""),621.0) -> 621 | D30: =IFERROR(__xludf.DUMMYFUNCTION("""COMPUTED_VALUE"""),"Completed") -> Completed
A31: =IFERROR(__xludf.DUMMYFUNCTION("""COMPUTED_VALUE"""),"G-REQ-00030") -> G-REQ-00030 | B31: =IFERROR(__xludf.DUMMYFUNCTION("""COMPUTED_VALUE"""),45763.4494871837) -> 45763.449 | C31: =IFERROR(__xludf.DUMMYFUNCTION("""COMPUTED_VALUE"""),625.0) -> 625 | D31: =IFERROR(__xludf.DUMMYFUNCTION("""COMPUTED_VALUE"""),"Completed") -> Completed
A32: =IFERROR(__xludf.DUMMYFUNCTION("""COMPUTED_VALUE"""),"G-REQ-00031") -> G-REQ-00031 | B32: =IFERROR(__xludf.DUMMYFUNCTION("""COMPUTED_VALUE"""),45763.520662029114) -> 45763.521 | C32: =IFERROR(__xludf.DUMMYFUNCTION("""COMPUTED_VALUE"""),629.0) -> 629 | D32: =IFERROR(__xludf.DUMMYFUNCTION("""COMPUTED_VALUE"""),"Completed") -> Completed
A33: =IFERROR(__xludf.DUMMYFUNCTION("""COMPUTED_VALUE"""),"G-REQ-00032") -> G-REQ-00032 | B33: =IFERROR(__xludf.DUMMYFUNCTION("""COMPUTED_VALUE"""),45763.58489243009) -> 45763.585 | C33: =IFERROR(__xludf.DUMMYFUNCTION("""COMPUTED_VALUE"""),631.0) -> 631 | D33: =IFERROR(__xludf.DUMMYFUNCTION("""COMPUTED_VALUE"""),"Cancelled") -> Cancelled
A34: =IFERROR(__xludf.DUMMYFUNCTION("""COMPUTED_VALUE"""),"G-REQ-00033") -> G-REQ-00033 | B34: =IFERROR(__xludf.DUMMYFUNCTION("""COMPUTED_VALUE"""),45763.66301171994) -> 45763.663 | C34: =IFERROR(__xludf.DUMMYFUNCTION("""COMPUTED_VALUE"""),635.0) -> 635 | D34: =IFERROR(__xludf.DUMMYFUNCTION("""COMPUTED_VALUE"""),"Completed") -> Completed
A35: =IFERROR(__xludf.DUMMYFUNCTION("""COMPUTED_VALUE"""),"G-REQ-00034") -> G-REQ-00034 | B35: =IFERROR(__xludf.DUMMYFUNCTION("""COMPUTED_VALUE"""),45763.72724212091) -> 45763.727 | C35: =IFERROR(__xludf.DUMMYFUNCTION("""COMPUTED_VALUE"""),637.0) -> 637 | D35: =IFERROR(__xludf.DUMMYFUNCTION("""COMPUTED_VALUE"""),"Cancelled") -> Cancelled
A36: =IFERROR(__xludf.DUMMYFUNCTION("""COMPUTED_VALUE"""),"G-REQ-00035") -> G-REQ-00035 | B36: =IFERROR(__xludf.DUMMYFUNCTION("""COMPUTED_VALUE"""),45763.80536141078) -> 45763.805 | C36: =IFERROR(__xludf.DUMMYFUNCTION("""COMPUTED_VALUE"""),641.0) -> 641 | D36: =IFERROR(__xludf.DUMMYFUNCTION("""COMPUTED_VALUE"""),"Completed") -> Completed
A37: =IFERROR(__xludf.DUMMYFUNCTION("""COMPUTED_VALUE"""),"G-REQ-00036") -> G-REQ-00036 | B37: =IFERROR(__xludf.DUMMYFUNCTION("""COMPUTED_VALUE"""),45763.87653625619) -> 45763.877 | C37: =IFERROR(__xludf.DUMMYFUNCTION("""COMPUTED_VALUE"""),645.0) -> 645 | D37: =IFERROR(__xludf.DUMMYFUNCTION("""COMPUTED_VALUE"""),"Completed") -> Completed
A38: =IFERROR(__xludf.DUMMYFUNCTION("""COMPUTED_VALUE"""),"G-REQ-00037") -> G-REQ-00037 | B38: =IFERROR(__xludf.DUMMYFUNCTION("""COMPUTED_VALUE"""),45763.94076665716) -> 45763.941 | C38: =IFERROR(__xludf.DUMMYFUNCTION("""COMPUTED_VALUE"""),647.0) -> 647 | D38: =IFERROR(__xludf.DUMMYFUNCTION("""COMPUTED_VALUE"""),"Cancelled") -> Cancelled
A39: =IFERROR(__xludf.DUMMYFUNCTION("""COMPUTED_VALUE"""),"G-REQ-00038") -> G-REQ-00038 | B39: =IFERROR(__xludf.DUMMYFUNCTION("""COMPUTED_VALUE"""),45764.01888594702) -> 45764.019 | C39: =IFERROR(__xludf.DUMMYFUNCTION("""COMPUTED_VALUE"""),651.0) -> 651 | D39: =IFERROR(__xludf.DUMMYFUNCTION("""COMPUTED_VALUE"""),"Completed") -> Completed
A40: =IFERROR(__xludf.DUMMYFUNCTION("""COMPUTED_VALUE"""),"G-REQ-00039") -> G-REQ-00039 | B40: =IFERROR(__xludf.DUMMYFUNCTION("""COMPUTED_VALUE"""),45764.090060792434) -> 45764.09 | C40: =IFERROR(__xludf.DUMMYFUNCTION("""COMPUTED_VALUE"""),655.0) -> 655 | D40: =IFERROR(__xludf.DUMMYFUNCTION("""COMPUTED_VALUE"""),"Completed") -> Completed
...
